[2022-07-28 15:09:40,886] {taskinstance.py:1179} INFO - Dependencies all met for <TaskInstance: META_historic_data.extract_historic_data_from_tda scheduled__2022-07-28T14:30:00+00:00 [queued]>
[2022-07-28 15:09:40,970] {taskinstance.py:1179} INFO - Dependencies all met for <TaskInstance: META_historic_data.extract_historic_data_from_tda scheduled__2022-07-28T14:30:00+00:00 [queued]>
[2022-07-28 15:09:40,978] {taskinstance.py:1376} INFO - 
--------------------------------------------------------------------------------
[2022-07-28 15:09:40,982] {taskinstance.py:1377} INFO - Starting attempt 1 of 2
[2022-07-28 15:09:40,983] {taskinstance.py:1378} INFO - 
--------------------------------------------------------------------------------
[2022-07-28 15:09:41,051] {taskinstance.py:1397} INFO - Executing <Task(PythonOperator): extract_historic_data_from_tda> on 2022-07-28 14:30:00+00:00
[2022-07-28 15:09:41,057] {standard_task_runner.py:52} INFO - Started process 810 to run task
[2022-07-28 15:09:41,087] {standard_task_runner.py:79} INFO - Running: ['***', 'tasks', 'run', 'META_historic_data', 'extract_historic_data_from_tda', 'scheduled__2022-07-28T14:30:00+00:00', '--job-id', '104', '--raw', '--subdir', 'DAGS_FOLDER/open_options.py', '--cfg-path', '/tmp/tmptcme4o_e', '--error-file', '/tmp/tmpwu0nobke']
[2022-07-28 15:09:41,103] {standard_task_runner.py:80} INFO - Job 104: Subtask extract_historic_data_from_tda
[2022-07-28 15:09:41,409] {task_command.py:371} INFO - Running <TaskInstance: META_historic_data.extract_historic_data_from_tda scheduled__2022-07-28T14:30:00+00:00 [running]> on host a2299eb83309
[2022-07-28 15:09:41,890] {taskinstance.py:1591} INFO - Exporting the following env vars:
AIRFLOW_CTX_DAG_OWNER=vardhan
AIRFLOW_CTX_DAG_ID=META_historic_data
AIRFLOW_CTX_TASK_ID=extract_historic_data_from_tda
AIRFLOW_CTX_EXECUTION_DATE=2022-07-28T14:30:00+00:00
AIRFLOW_CTX_TRY_NUMBER=1
AIRFLOW_CTX_DAG_RUN_ID=scheduled__2022-07-28T14:30:00+00:00
[2022-07-28 15:10:05,592] {taskinstance.py:1909} ERROR - Task failed with exception
Traceback (most recent call last):
  File "/home/airflow/.local/lib/python3.7/site-packages/urllib3/connectionpool.py", line 710, in urlopen
    chunked=chunked,
  File "/home/airflow/.local/lib/python3.7/site-packages/urllib3/connectionpool.py", line 386, in _make_request
    self._validate_conn(conn)
  File "/home/airflow/.local/lib/python3.7/site-packages/urllib3/connectionpool.py", line 1040, in _validate_conn
    conn.connect()
  File "/home/airflow/.local/lib/python3.7/site-packages/urllib3/connection.py", line 424, in connect
    tls_in_tls=tls_in_tls,
  File "/home/airflow/.local/lib/python3.7/site-packages/urllib3/util/ssl_.py", line 450, in ssl_wrap_socket
    sock, context, tls_in_tls, server_hostname=server_hostname
  File "/home/airflow/.local/lib/python3.7/site-packages/urllib3/util/ssl_.py", line 493, in _ssl_wrap_socket_impl
    return ssl_context.wrap_socket(sock, server_hostname=server_hostname)
  File "/usr/local/lib/python3.7/ssl.py", line 423, in wrap_socket
    session=session
  File "/usr/local/lib/python3.7/ssl.py", line 870, in _create
    self.do_handshake()
  File "/usr/local/lib/python3.7/ssl.py", line 1139, in do_handshake
    self._sslobj.do_handshake()
OSError: [Errno 0] Error

During handling of the above exception, another exception occurred:

Traceback (most recent call last):
  File "/home/airflow/.local/lib/python3.7/site-packages/requests/adapters.py", line 499, in send
    timeout=timeout,
  File "/home/airflow/.local/lib/python3.7/site-packages/urllib3/connectionpool.py", line 786, in urlopen
    method, url, error=e, _pool=self, _stacktrace=sys.exc_info()[2]
  File "/home/airflow/.local/lib/python3.7/site-packages/urllib3/util/retry.py", line 550, in increment
    raise six.reraise(type(error), error, _stacktrace)
  File "/home/airflow/.local/lib/python3.7/site-packages/urllib3/packages/six.py", line 769, in reraise
    raise value.with_traceback(tb)
  File "/home/airflow/.local/lib/python3.7/site-packages/urllib3/connectionpool.py", line 710, in urlopen
    chunked=chunked,
  File "/home/airflow/.local/lib/python3.7/site-packages/urllib3/connectionpool.py", line 386, in _make_request
    self._validate_conn(conn)
  File "/home/airflow/.local/lib/python3.7/site-packages/urllib3/connectionpool.py", line 1040, in _validate_conn
    conn.connect()
  File "/home/airflow/.local/lib/python3.7/site-packages/urllib3/connection.py", line 424, in connect
    tls_in_tls=tls_in_tls,
  File "/home/airflow/.local/lib/python3.7/site-packages/urllib3/util/ssl_.py", line 450, in ssl_wrap_socket
    sock, context, tls_in_tls, server_hostname=server_hostname
  File "/home/airflow/.local/lib/python3.7/site-packages/urllib3/util/ssl_.py", line 493, in _ssl_wrap_socket_impl
    return ssl_context.wrap_socket(sock, server_hostname=server_hostname)
  File "/usr/local/lib/python3.7/ssl.py", line 423, in wrap_socket
    session=session
  File "/usr/local/lib/python3.7/ssl.py", line 870, in _create
    self.do_handshake()
  File "/usr/local/lib/python3.7/ssl.py", line 1139, in do_handshake
    self._sslobj.do_handshake()
urllib3.exceptions.ProtocolError: ('Connection aborted.', OSError(0, 'Error'))

During handling of the above exception, another exception occurred:

Traceback (most recent call last):
  File "/home/airflow/.local/lib/python3.7/site-packages/airflow/operators/python.py", line 171, in execute
    return_value = self.execute_callable()
  File "/home/airflow/.local/lib/python3.7/site-packages/airflow/operators/python.py", line 189, in execute_callable
    return self.python_callable(*self.op_args, **self.op_kwargs)
  File "/opt/airflow/dags/open_options.py", line 112, in extract_historic_data_from_tda
    params=params
  File "/home/airflow/.local/lib/python3.7/site-packages/requests/api.py", line 73, in get
    return request("get", url, params=params, **kwargs)
  File "/home/airflow/.local/lib/python3.7/site-packages/requests/api.py", line 59, in request
    return session.request(method=method, url=url, **kwargs)
  File "/home/airflow/.local/lib/python3.7/site-packages/requests/sessions.py", line 587, in request
    resp = self.send(prep, **send_kwargs)
  File "/home/airflow/.local/lib/python3.7/site-packages/requests/sessions.py", line 701, in send
    r = adapter.send(request, **kwargs)
  File "/home/airflow/.local/lib/python3.7/site-packages/requests/adapters.py", line 547, in send
    raise ConnectionError(err, request=request)
requests.exceptions.ConnectionError: ('Connection aborted.', OSError(0, 'Error'))
[2022-07-28 15:10:05,614] {taskinstance.py:1420} INFO - Marking task as UP_FOR_RETRY. dag_id=META_historic_data, task_id=extract_historic_data_from_tda, execution_date=20220728T143000, start_date=20220728T150940, end_date=20220728T151005
[2022-07-28 15:10:05,635] {standard_task_runner.py:97} ERROR - Failed to execute job 104 for task extract_historic_data_from_tda (('Connection aborted.', OSError(0, 'Error')); 810)
[2022-07-28 15:10:05,673] {local_task_job.py:156} INFO - Task exited with return code 1
[2022-07-28 15:10:05,933] {local_task_job.py:273} INFO - 0 downstream tasks scheduled from follow-on schedule check
