[2022-07-28 15:09:45,455] {taskinstance.py:1179} INFO - Dependencies all met for <TaskInstance: MSFT_historic_data.extract_historic_data_from_tda scheduled__2022-07-28T14:30:00+00:00 [queued]>
[2022-07-28 15:09:45,518] {taskinstance.py:1179} INFO - Dependencies all met for <TaskInstance: MSFT_historic_data.extract_historic_data_from_tda scheduled__2022-07-28T14:30:00+00:00 [queued]>
[2022-07-28 15:09:45,519] {taskinstance.py:1376} INFO - 
--------------------------------------------------------------------------------
[2022-07-28 15:09:45,519] {taskinstance.py:1377} INFO - Starting attempt 1 of 2
[2022-07-28 15:09:45,519] {taskinstance.py:1378} INFO - 
--------------------------------------------------------------------------------
[2022-07-28 15:09:45,588] {taskinstance.py:1397} INFO - Executing <Task(PythonOperator): extract_historic_data_from_tda> on 2022-07-28 14:30:00+00:00
[2022-07-28 15:09:45,593] {standard_task_runner.py:52} INFO - Started process 829 to run task
[2022-07-28 15:09:45,608] {standard_task_runner.py:79} INFO - Running: ['***', 'tasks', 'run', 'MSFT_historic_data', 'extract_historic_data_from_tda', 'scheduled__2022-07-28T14:30:00+00:00', '--job-id', '112', '--raw', '--subdir', 'DAGS_FOLDER/open_options.py', '--cfg-path', '/tmp/tmp7igmi02t', '--error-file', '/tmp/tmpzfa3sraw']
[2022-07-28 15:09:45,631] {standard_task_runner.py:80} INFO - Job 112: Subtask extract_historic_data_from_tda
[2022-07-28 15:09:45,941] {task_command.py:371} INFO - Running <TaskInstance: MSFT_historic_data.extract_historic_data_from_tda scheduled__2022-07-28T14:30:00+00:00 [running]> on host a2299eb83309
[2022-07-28 15:09:46,548] {taskinstance.py:1591} INFO - Exporting the following env vars:
AIRFLOW_CTX_DAG_OWNER=vardhan
AIRFLOW_CTX_DAG_ID=MSFT_historic_data
AIRFLOW_CTX_TASK_ID=extract_historic_data_from_tda
AIRFLOW_CTX_EXECUTION_DATE=2022-07-28T14:30:00+00:00
AIRFLOW_CTX_TRY_NUMBER=1
AIRFLOW_CTX_DAG_RUN_ID=scheduled__2022-07-28T14:30:00+00:00
[2022-07-28 15:10:29,159] {taskinstance.py:1909} ERROR - Task failed with exception
Traceback (most recent call last):
  File "/home/airflow/.local/lib/python3.7/site-packages/urllib3/connection.py", line 175, in _new_conn
    (self._dns_host, self.port), self.timeout, **extra_kw
  File "/home/airflow/.local/lib/python3.7/site-packages/urllib3/util/connection.py", line 95, in create_connection
    raise err
  File "/home/airflow/.local/lib/python3.7/site-packages/urllib3/util/connection.py", line 85, in create_connection
    sock.connect(sa)
ConnectionRefusedError: [Errno 111] Connection refused

During handling of the above exception, another exception occurred:

Traceback (most recent call last):
  File "/home/airflow/.local/lib/python3.7/site-packages/urllib3/connectionpool.py", line 710, in urlopen
    chunked=chunked,
  File "/home/airflow/.local/lib/python3.7/site-packages/urllib3/connectionpool.py", line 386, in _make_request
    self._validate_conn(conn)
  File "/home/airflow/.local/lib/python3.7/site-packages/urllib3/connectionpool.py", line 1040, in _validate_conn
    conn.connect()
  File "/home/airflow/.local/lib/python3.7/site-packages/urllib3/connection.py", line 358, in connect
    self.sock = conn = self._new_conn()
  File "/home/airflow/.local/lib/python3.7/site-packages/urllib3/connection.py", line 187, in _new_conn
    self, "Failed to establish a new connection: %s" % e
urllib3.exceptions.NewConnectionError: <urllib3.connection.HTTPSConnection object at 0x7efe990e2150>: Failed to establish a new connection: [Errno 111] Connection refused

During handling of the above exception, another exception occurred:

Traceback (most recent call last):
  File "/home/airflow/.local/lib/python3.7/site-packages/requests/adapters.py", line 499, in send
    timeout=timeout,
  File "/home/airflow/.local/lib/python3.7/site-packages/urllib3/connectionpool.py", line 786, in urlopen
    method, url, error=e, _pool=self, _stacktrace=sys.exc_info()[2]
  File "/home/airflow/.local/lib/python3.7/site-packages/urllib3/util/retry.py", line 592, in increment
    raise MaxRetryError(_pool, url, error or ResponseError(cause))
urllib3.exceptions.MaxRetryError: HTTPSConnectionPool(host='api.tdameritrade.com', port=443): Max retries exceeded with url: /v1/marketdata/MSFT/pricehistory?apikey=W2KCGVWHV34K0OZT74Q2ZDZ751FGRXUT&startDate=1627499386 (Caused by NewConnectionError('<urllib3.connection.HTTPSConnection object at 0x7efe990e2150>: Failed to establish a new connection: [Errno 111] Connection refused'))

During handling of the above exception, another exception occurred:

Traceback (most recent call last):
  File "/home/airflow/.local/lib/python3.7/site-packages/airflow/operators/python.py", line 171, in execute
    return_value = self.execute_callable()
  File "/home/airflow/.local/lib/python3.7/site-packages/airflow/operators/python.py", line 189, in execute_callable
    return self.python_callable(*self.op_args, **self.op_kwargs)
  File "/opt/airflow/dags/open_options.py", line 112, in extract_historic_data_from_tda
    params=params
  File "/home/airflow/.local/lib/python3.7/site-packages/requests/api.py", line 73, in get
    return request("get", url, params=params, **kwargs)
  File "/home/airflow/.local/lib/python3.7/site-packages/requests/api.py", line 59, in request
    return session.request(method=method, url=url, **kwargs)
  File "/home/airflow/.local/lib/python3.7/site-packages/requests/sessions.py", line 587, in request
    resp = self.send(prep, **send_kwargs)
  File "/home/airflow/.local/lib/python3.7/site-packages/requests/sessions.py", line 701, in send
    r = adapter.send(request, **kwargs)
  File "/home/airflow/.local/lib/python3.7/site-packages/requests/adapters.py", line 565, in send
    raise ConnectionError(e, request=request)
requests.exceptions.ConnectionError: HTTPSConnectionPool(host='api.tdameritrade.com', port=443): Max retries exceeded with url: /v1/marketdata/MSFT/pricehistory?apikey=W2KCGVWHV34K0OZT74Q2ZDZ751FGRXUT&startDate=1627499386 (Caused by NewConnectionError('<urllib3.connection.HTTPSConnection object at 0x7efe990e2150>: Failed to establish a new connection: [Errno 111] Connection refused'))
[2022-07-28 15:10:29,188] {taskinstance.py:1420} INFO - Marking task as UP_FOR_RETRY. dag_id=MSFT_historic_data, task_id=extract_historic_data_from_tda, execution_date=20220728T143000, start_date=20220728T150945, end_date=20220728T151029
[2022-07-28 15:10:29,211] {standard_task_runner.py:97} ERROR - Failed to execute job 112 for task extract_historic_data_from_tda (HTTPSConnectionPool(host='api.tdameritrade.com', port=443): Max retries exceeded with url: /v1/marketdata/MSFT/pricehistory?apikey=W2KCGVWHV34K0OZT74Q2ZDZ751FGRXUT&startDate=1627499386 (Caused by NewConnectionError('<urllib3.connection.HTTPSConnection object at 0x7efe990e2150>: Failed to establish a new connection: [Errno 111] Connection refused')); 829)
[2022-07-28 15:10:29,250] {local_task_job.py:156} INFO - Task exited with return code 1
[2022-07-28 15:10:29,520] {local_task_job.py:273} INFO - 0 downstream tasks scheduled from follow-on schedule check
